ERROR 2023-05-30 11:13:08,705 views An exception occurred while retrieving the why you learn for course
Traceback (most recent call last):
  File "/home/hp/Desktop/IntenshipP30May/thoughtwin-internship-backend/internship_product/apps/courses/views.py", line 157, in get
    instance = self.get_queryset(user_course_id).first()
  File "/home/hp/Desktop/IntenshipP30May/thoughtwin-internship-backend/internship_product/apps/courses/views.py", line 150, in get_queryset
    user_course = UserCourse.objects.get(id = user_course_id)
  File "/home/hp/Desktop/IntenshipP30May/thoughtwin-internship-backend/env/lib/python3.8/site-packages/django/db/models/manager.py", line 85, in manager_method
    return getattr(self.get_queryset(), name)(*args, **kwargs)
  File "/home/hp/Desktop/IntenshipP30May/thoughtwin-internship-backend/env/lib/python3.8/site-packages/django/db/models/query.py", line 650, in get
    raise self.model.DoesNotExist(
apps.student.models.UserCourse.DoesNotExist: UserCourse matching query does not exist.
